Workbook

Sheet Parametros
B2: PARÁMETROS — editar sólo las celdas en azul sobre fondo crema
B3: Alícuotas y bases de cálculo. Todo lo demás en el libro se calcula desde acá.
B5: 1. CONTRIBUCIONES PATRONALES (SÍ son costo de la empresa)
B6: Concepto | C6: Alícuota | D6: Base | E6: Referencia legal / nota
B7: SUSS (SIPA + INSSJP + FNE + Asig. Familiares) | C7: 0.18 | D7: Remunerativo | E7: Ley 27.541 art. 19 inc. b): 18% PyME/industria/construcción. 20,40% si es empresa grande de servicios o comercio.
B8: Obra social patronal | C8: 0.06 | D8: Remunerativo | E8: Ley 23.660. Se calcula aparte del SUSS, sobre el bruto.
B9: ART — alícuota variable | C9: 0.1023 | D9: Remunerativo | E9: SUPUESTO A REEMPLAZAR: 10,23% viene de la planilla de la liquidadora, no de una póliza verificada. Poner el valor real.
B10: Fondo de Cese Laboral | C10: 0.12 | D10: Remunerativo | E10: Ley 22.250: 12% el 1er año, 8% desde el año de antigüedad. Se deja 12%: con la rotación de obra pocos operarios llegan al año.
B11: UOCRA empleador | C11: 0.02 | D11: Remunerativo | E11: Contribución patronal al sindicato.
B12: FICS (2% s/ Fondo de Cese) | C12: 0.02 | D12: Fondo de Cese | E12: Se calcula sobre el FCL, no sobre el sueldo. Equivale a 0,24% del remunerativo si el FCL es 12%.
B13: IERIC (1% s/ Fondo de Cese) | C13: 0.01 | D13: Fondo de Cese | E13: Idem: base = FCL, no sueldo.
B14: FODECO (1% s/ Fondo de Cese) | C14: 0.01 | D14: Fondo de Cese | E14: Idem: base = FCL, no sueldo.
B15: Total % sobre remunerativo | C15: =C7+C8+C9+C10+C11+C10*(C12+C13+C14) -> 0.4871 | E15: Suma efectiva aplicada al remunerativo (los tres últimos ya convertidos desde su base FCL).
B17: 2. COSTOS FIJOS DEL EMPLEADOR ($ por operario por mes)
B18: Concepto | C18: Importe | E18: Nota
B19: ART — suma fija por trabajador | C19: 1905 | E19: Fijo por operario, además de la alícuota.
B20: Seguro de Vida Obligatorio (empleador) | C20: 424.62 | E20: Decreto 1567/74.
B21: Preocupacional | C21: 23333.33 | E21: Promedio mensual anual (costo del estudio prorrateado).
B22: Indumentaria y EPP | C22: 29681.83 | E22: Promedio mensual semestral (2 entregas por año).
B23: Telegramas / gestión | C23: 2000 | E23: Promedio anual.
B24: Total fijos empleador | C24: =SUM(C19:C23) -> 57344.78
B26: 3. APORTES DEL TRABAJADOR — NO son costo de la empresa
B27: Se retienen del sueldo bruto y se depositan; no se suman al costo empresa. Van acá sólo para calcular el neto de bolsillo.
B28: Concepto | C28: Alícuota | E28: Referencia
B29: Jubilación (SIPA) | C29: 0.11 | E29: Ley 24.241.
B30: INSSJP / PAMI | C30: 0.03 | E30: Ley 19.032.
B31: Obra social | C31: 0.03 | E31: Ley 23.660.
B32: Cuota sindical UOCRA (afiliado) | C32: 0.025 | E32: Acuerdos 2026. No afiliado: aporte solidario 2%.
B33: Seguro de Vida UOCRA (empleado, $ fijo) | C33: 19617.16 | E33: Descontado al trabajador. NO es costo empresa.
B34: Total aportes trabajador | C34: =SUM(C29:C32) -> 0.195
B36: 4. BASE REMUNERATIVA
B37: Horas mes según convenio | C37: 176 | E37: CCT 76/75 art. 11: 44 hs semanales. 176 = 4 semanas (criterio de la liquidadora). El promedio real del mes es 190,67 hs.
B38: SAC (aguinaldo) — proporción mensual | C38: 0.083333333 | E38: Un doceavo. Se prorratea para que cada mes absorba su parte y junio no distorsione.
B39: Vacaciones — jornales por mes | C39: 1 | E39: 1 jornal/mes = 12 jornales/año. Se pagan como no gozadas por la alta rotación del sector.
B40: Asistencia perfecta — % de referencia | C40: 0.2 | E40: Informativo. El % efectivo se carga por categoría en la hoja Escala UOCRA (Sereno liquida 22%).
B41: ¿Aplica adicional hormigón en el valor hora base? | C41: 0 | D41: 0 = No · 1 = Sí | E41: DECIDIDO: 0. El adicional NO va en el valor hora base — corresponde sólo a tareas de hormigón. Se aplica dentro de las APU de estructura, donde sí corresponde.
B43: 5. HORAS PRODUCTIVAS (horas pagadas que NO se trabajan)
B44: Este bloque es el que faltaba en la planilla original. Se paga el mes completo pero no todas las horas producen.
B45: Concepto | C45: Valor | D45: Unidad | E45: Nota
B46: Feriados | C46: 8 | D46: hs/mes | E46: ≈12 feriados en día hábil por año × 8 hs ÷ 12 meses. Ajustar según calendario.
...

Sheet Escala UOCRA
B2: ESCALA SALARIAL — UOCRA CCT 76/75 · Zona B · septiembre 2026
B3: Actualizar estos valores en cada paritaria. Es lo único que cambia mes a mes.
B5: Concepto | C5: Ayudante | D5: Medio Oficial | E5: Oficial | F5: Oficial Especializado | G5: Sereno | H5: Nota
B6: Jornal básico de convenio | C6: 5399 | D6: 5866 | E6: 6348 | F6: 7420 | G6: 980858 | H6: Ayudante a Of. Especializado: por hora. Sereno: mensual.
B7: Zona B (desfavorable) | C7: 621 | D7: 636 | E7: 702 | F7: 816 | G7: 111861 | H7: Adicional por zona desfavorable del convenio.
B8: Adicional hormigón | C8: 0 | D8: 0 | E8: 0 | F8: 0 | G8: 0 | H8: Cargado pero NO aplicado al valor hora base (interruptor en 0). Se suma dentro de las APU de estructura.
B9: Subtotal base | C9: =C6+C7+C8*Parametros!$C$41 -> 6020 | D9: =D6+D7+D8*Parametros!$C$41 -> 6502 | E9: =E6+E7+E8*Parametros!$C$41 -> 7050 | F9: =F6+F7+F8*Parametros!$C$41 -> 8236 | G9: =G6+G7+G8*Parametros!$C$41 -> 1092719 | H9: Básico + zona + (hormigón × interruptor de Parámetros). Con el interruptor en 0 el adicional queda afuera.
B10: % asistencia perfecta | C10: 0.2 | D10: 0.2 | E10: 0.2 | F10: 0.2 | G10: 0.22 | H10: El Sereno liquida 22%, las demás categorías 20%. Verificar en cada escala.
B11: Asistencia perfecta ($) | C11: =C9*C10 -> 1204 | D11: =D9*D10 -> 1300.4 | E11: =E9*E10 -> 1410 | F11: =F9*F10 -> 1647.2 | G11: =G9*G10 -> 240398.18 | H11: Subtotal base × % de la fila anterior.
B12: TOTAL JORNAL / MES | C12: =C9+C11 -> 7224 | D12: =D9+D11 -> 7802.4 | E12: =E9+E11 -> 8460 | F12: =F9+F11 -> 9883.2 | G12: =G9+G11 -> 1333117.2 | H12: Valor hora para las 4 primeras categorías; valor mensual para Sereno.
B14: Tipo de liquidación | C14: Por hora | D14: Por hora | E14: Por hora | F14: Por hora | G14: Mensual | H14: El Sereno se liquida por mes, no por hora: su costo/hora sale del mensual dividido las horas productivas.

Sheet Calculo
B2: CÁLCULO DEL COSTO EMPRESA POR CATEGORÍA
C3: Todo se calcula desde 'Parametros' y 'Escala UOCRA'. No editar nada de esta hoja.
B5: N° | C5: Concepto | D5: Ayudante | E5: Medio Oficial | F5: Oficial | G5: Oficial Especializado | H5: Sereno
C7: A. BASE REMUNERATIVA MENSUAL
B8: 1 | C8: Remuneración mensual | D8: ='Escala UOCRA'!C12*Parametros!$C$37 -> 1271424 | E8: ='Escala UOCRA'!D12*Parametros!$C$37 -> 1373222.4 | F8: ='Escala UOCRA'!E12*Parametros!$C$37 -> 1488960 | G8: ='Escala UOCRA'!F12*Parametros!$C$37 -> 1739443.2 | H8: ='Escala UOCRA'!G12 -> 1333117.2
B9: 2 | C9: SAC (aguinaldo) prorrateado | D9: =D8*Parametros!$C$38 -> 105952 | E9: =E8*Parametros!$C$38 -> 114435.2 | F9: =F8*Parametros!$C$38 -> 124080 | G9: =G8*Parametros!$C$38 -> 144953.6 | H9: =H8*Parametros!$C$38 -> 111093.1
B10: 3 | C10: Vacaciones | D10: ='Escala UOCRA'!C12*8*Parametros!$C$39 -> 57792 | E10: ='Escala UOCRA'!D12*8*Parametros!$C$39 -> 62419.2 | F10: ='Escala UOCRA'!E12*8*Parametros!$C$39 -> 67680 | G10: ='Escala UOCRA'!F12*8*Parametros!$C$39 -> 79065.6 | H10: =H8/25*Parametros!$C$39 -> 53324.687
B11: 4 | C11: TOTAL REMUNERATIVO | D11: =SUM(D8:D10) -> 1435168 | E11: =SUM(E8:E10) -> 1550076.8 | F11: =SUM(F8:F10) -> 1680720 | G11: =SUM(G8:G10) -> 1963462.4 | H11: =SUM(H8:H10) -> 1497535
C13: B. CONTRIBUCIONES PATRONALES (costo de la empresa)
B14: 5 | C14: SUSS (SIPA + PAMI + FNE + Asig. Fam.) | D14: =D11*Parametros!$C$7 -> 258330.24 | E14: =E11*Parametros!$C$7 -> 279013.82 | F14: =F11*Parametros!$C$7 -> 302529.6 | G14: =G11*Parametros!$C$7 -> 353423.23 | H14: =H11*Parametros!$C$7 -> 269556.29
B15: 6 | C15: Obra social patronal | D15: =D11*Parametros!$C$8 -> 86110.08 | E15: =E11*Parametros!$C$8 -> 93004.608 | F15: =F11*Parametros!$C$8 -> 100843.2 | G15: =G11*Parametros!$C$8 -> 117807.74 | H15: =H11*Parametros!$C$8 -> 89852.098
B16: 7 | C16: ART (alícuota) | D16: =D11*Parametros!$C$9 -> 146817.69 | E16: =E11*Parametros!$C$9 -> 158572.86 | F16: =F11*Parametros!$C$9 -> 171937.66 | G16: =G11*Parametros!$C$9 -> 200862.2 | H16: =H11*Parametros!$C$9 -> 153197.83
B17: 8 | C17: Fondo de Cese Laboral | D17: =D11*Parametros!$C$10 -> 172220.16 | E17: =E11*Parametros!$C$10 -> 186009.22 | F17: =F11*Parametros!$C$10 -> 201686.4 | G17: =G11*Parametros!$C$10 -> 235615.49 | H17: =H11*Parametros!$C$10 -> 179704.2
B18: 9 | C18: UOCRA empleador | D18: =D11*Parametros!$C$11 -> 28703.36 | E18: =E11*Parametros!$C$11 -> 31001.536 | F18: =F11*Parametros!$C$11 -> 33614.4 | G18: =G11*Parametros!$C$11 -> 39269.248 | H18: =H11*Parametros!$C$11 -> 29950.699
B19: 10 | C19: FICS (s/ Fondo de Cese) | D19: =D17*Parametros!$C$12 -> 3444.4032 | E19: =E17*Parametros!$C$12 -> 3720.1843 | F19: =F17*Parametros!$C$12 -> 4033.728 | G19: =G17*Parametros!$C$12 -> 4712.3098 | H19: =H17*Parametros!$C$12 -> 3594.0839
B20: 11 | C20: IERIC (s/ Fondo de Cese) | D20: =D17*Parametros!$C$13 -> 1722.2016 | E20: =E17*Parametros!$C$13 -> 1860.0922 | F20: =F17*Parametros!$C$13 -> 2016.864 | G20: =G17*Parametros!$C$13 -> 2356.1549 | H20: =H17*Parametros!$C$13 -> 1797.042
B21: 12 | C21: FODECO (s/ Fondo de Cese) | D21: =D17*Parametros!$C$14 -> 1722.2016 | E21: =E17*Parametros!$C$14 -> 1860.0922 | F21: =F17*Parametros!$C$14 -> 2016.864 | G21: =G17*Parametros!$C$14 -> 2356.1549 | H21: =H17*Parametros!$C$14 -> 1797.042
B22: 13 | C22: Subtotal contribuciones | D22: =SUM(D14:D21) -> 699070.33 | E22: =SUM(E14:E21) -> 755042.41 | F22: =SUM(F14:F21) -> 818678.71 | G22: =SUM(G14:G21) -> 956402.54 | H22: =SUM(H14:H21) -> 729449.28
C24: C. COSTOS FIJOS DEL EMPLEADOR
B25: 14 | C25: Fijos por operario / mes | D25: =Parametros!$C$24 -> 57344.78 | E25: =Parametros!$C$24 -> 57344.78 | F25: =Parametros!$C$24 -> 57344.78 | G25: =Parametros!$C$24 -> 57344.78 | H25: =Parametros!$C$24 -> 57344.78
C27: D. COSTO EMPRESA
B28: 15 | C28: COSTO TOTAL MENSUAL | D28: =D11+D22+D25 -> 2191583.1 | E28: =E11+E22+E25 -> 2362464 | F28: =F11+F22+F25 -> 2556743.5 | G28: =G11+G22+G25 -> 2977209.7 | H28: =H11+H22+H25 -> 2284329
B29: 16 | C29: Costo por hora NOMINAL (÷ horas convenio) | D29: =D28/Parametros!$C$37 -> 12452.177 | E29: =E28/Parametros!$C$37 -> 13423.091 | F29: =F28/Parametros!$C$37 -> 14526.952 | G29: =G28/Parametros!$C$37 -> 16915.964 | H29: =H28/Parametros!$C$37 -> 12979.142
B30: 17 | C30: COSTO POR HORA PRODUCTIVA | D30: =D28/Parametros!$C$51 -> 13562.616 | E30: =E28/Parametros!$C$51 -> 14620.113 | F30: =F28/Parametros!$C$51 -> 15822.412 | G30: =G28/Parametros!$C$51 -> 18424.468 | H30: =H28/Parametros!$C$51 -> 14136.574
C32: E. VERIFICACIÓN Y MULTIPLICADORES
B33: 18 | C33: Multiplicador s/ jornal de convenio | D33: =D28/('Escala UOCRA'!C12*Parametros!$C$37) -> 1.7237233 | E33: =E28/('Escala UOCRA'!D12*Parametros!$C$37) -> 1.7203797 | F33: =F28/('Escala UOCRA'!E12*Parametros!$C$37) -> 1.7171338 | G33: =G28/('Escala UOCRA'!F12*Parametros!$C$37) -> 1.7115878 | H33: =H28/('Escala UOCRA'!G12) -> 1.7135246
B34: 19 | C34: % de cargas s/ remunerativo | D34: =(D22+D25)/D11 -> 0.52705684 | E34: =(E22+E25)/E11 -> 0.5240948 | F34: =(F22+F25)/F11 -> 0.52121918 | G34: =(G22+G25)/G11 -> 0.51630595 | H34: =(H22+H25)/H11 -> 0.52539278
C36: F. APORTES DEL TRABAJADOR — NO integran el costo empresa
B37: 20 | C37: Aportes de ley + sindical | D37: =D11*Parametros!$C$34 -> 279857.76 | E37: =E11*Parametros!$C$34 -> 302264.98 | F37: =F11*Parametros!$C$34 -> 327740.4 | G37: =G11*Parametros!$C$34 -> 382875.17 | H37: =H11*Parametros!$C$34 -> 292019.32
B38: 21 | C38: Seguro de vida UOCRA (empleado) | D38: =Parametros!$C$33 -> 19617.16 | E38: =Parametros!$C$33 -> 19617.16 | F38: =Parametros!$C$33 -> 19617.16 | G38: =Parametros!$C$33 -> 19617.16 | H38: =Parametros!$C$33 -> 19617.16
B39: 22 | C39: Sueldo NETO de bolsillo | D39: =D11-D37-D38 -> 1135693.1 | E39: =E11-E37-E38 -> 1228194.7 | F39: =F11-F37-F38 -> 1333362.4 | G39: =G11-G37-G38 -> 1560970.1 | H39: =H11-H37-H38 -> 1185898.5
C41: Las líneas 20 a 22 se muestran sólo para conocer el neto del operario. Sumarlas al costo empresa es el error de la planilla original.

Sheet Resumen
B2: VALOR HORA PARA CARGAR EN LA APU
B3: Este es el número que va a la solapa Materiales y MO de computoPRO.
B5: Categoría | C5: Costo/hora productiva | D5: Costo/hora nominal | E5: Costo mensual | F5: Multiplicador | G5: Nota
B6: Ayudante | C6: =Calculo!D30 -> 13562.616 | D6: =Calculo!D29 -> 12452.177 | E6: =Calculo!D28 -> 2191583.1 | F6: =Calculo!D33 -> 1.7237233
B7: Medio Oficial | C7: =Calculo!E30 -> 14620.113 | D7: =Calculo!E29 -> 13423.091 | E7: =Calculo!E28 -> 2362464 | F7: =Calculo!E33 -> 1.7203797
B8: Oficial | C8: =Calculo!F30 -> 15822.412 | D8: =Calculo!F29 -> 14526.952 | E8: =Calculo!F28 -> 2556743.5 | F8: =Calculo!F33 -> 1.7171338
B9: Oficial Especializado | C9: =Calculo!G30 -> 18424.468 | D9: =Calculo!G29 -> 16915.964 | E9: =Calculo!G28 -> 2977209.7 | F9: =Calculo!G33 -> 1.7115878
B10: Sereno | C10: =Calculo!H30 -> 14136.574 | D10: =Calculo!H29 -> 12979.142 | E10: =Calculo!H28 -> 2284329 | F10: =Calculo!H33 -> 1.7135246 | G10: Liquidación mensual. El costo/hora es referencial.
B12: COMPARACIÓN CONTRA LA PLANILLA ORIGINAL (sept-2026)
B13: Categoría | C13: Esta planilla | D13: Planilla original | E13: Diferencia | F13: Dif. % | G13: Motivo
B14: Ayudante | C14: =C6 -> 13562.616 | D14: 15229.48 | E14: =C14-D14 -> -1666.864 | F14: =IFERROR(C14/D14-1,0) -> -0.10944983 | G14: La original suma los aportes del trabajador al costo (lo infla) y divide por 176 hs nominales (lo desinfla). Los dos errores se compensan en parte.
B15: Medio Oficial | C15: =C7 -> 14620.113 | D15: 16413.84 | E15: =C15-D15 -> -1793.7274 | F15: =IFERROR(C15/D15-1,0) -> -0.1092814
B16: Oficial | C16: =C8 -> 15822.412 | D16: 17760.37 | E16: =C16-D16 -> -1937.9584 | F16: =IFERROR(C16/D16-1,0) -> -0.10911701
B17: Oficial Especializado | C17: =C9 -> 18424.468 | D17: 20674.58 | E17: =C17-D17 -> -2250.1124 | F17: =IFERROR(C17/D17-1,0) -> -0.10883473
B18: Sereno | C18: =C10 -> 14136.574 | D18: 14495.93 | E18: =C18-D18 -> -359.35579 | F18: =IFERROR(C18/D18-1,0) -> -0.024790116
B21: QUÉ CAMBIAR CUANDO
B23: Paritaria UOCRA | C23: Hoja 'Escala UOCRA', filas 6 a 8. Es lo único que cambia cada 3-4 meses.
B24: Póliza de ART | C24: Parámetros, alícuota ART y suma fija. Depende de tu empresa, no de la ley.
B25: Operario supera el año de antigüedad | C25: Parámetros, Fondo de Cese: 12% → 8%.
B26: Empresa deja de ser PyME | C26: Parámetros, SUSS: 18% → 20,40%.
B27: Obra con muchas paradas por clima | C27: Parámetros, 'Paradas por clima'. Sube el costo por hora productiva.
B28: Cambio de zona | C28: Hoja 'Escala UOCRA', fila 7. Zona B es la de Patagonia Norte.
B30: ADVERTENCIAS
B31: 1. DECIDIDO: el adicional por hormigón NO está incluido en el valor hora base. Corresponde sólo a tareas de hormigón, así que se aplica dentro de las APU de estructura. En la app va activado por defecto en esos rubros para todos; poder desactivarlo es función PRO.
B32: 2. Horas mes: 176 (4 semanas × 44 hs), que es lo que usa la liquidadora. El promedio real del convenio es 190,67 hs (44 × 52 ÷ 12). Cambiarlo mueve el valor hora sólo 0,5%, pero sube el costo mensual ~8%.
B33: 3. Fondo de Cese al 12% (primer año, criterio conservador). Bajarlo a 8% para cuadrilla con más de un año de antigüedad reduce el valor hora ~2,7%.
B34: 4. ART al 10,23%: es el valor de la planilla de la liquidadora, NO está verificado contra tu póliza. Es el único parámetro que hay que reemplazar sí o sí por el número real de tu ART. Cada punto de ART mueve el valor hora ~0,65%.
