Workbook

Sheet Hoja2
A2: Estructura de hierro | K2: =K30+K40+K51 -> 2496.1152 | L2: kg | M2: 4.5 | N2: 1 | O2: =N2*M2*K2 -> 11232.518 | Q2: =O2*380 -> 4268357 | R2: =K2*1.3 -> 3244.9498 | S2: =R2*380 -> 1233080.9
A4: anclajes metalicos para T2-T2 (vigas F - Vigas PB) | O4: =115*2700 -> 310500 | Q4: =10*12000*6 -> 720000
Q5: =Q4*3 -> 2160000
A6: descripcion | B6: cantidad | D6: unidades | E6: total sup | G6: peso x m2 | I6: total peso | K6: =200*14500 -> 2900000 | O6: =SUM(O2:O4) -> 321732.52
A7: CHAPA 200x100x4,76 | B7: 0.02 | C7: m2 | D7: 24 | E7: =D7*B7 -> 0.48 | F7: m2 | G7: 37.68 | H7: kg/m2 | I7: =G7*E7 -> 18.0864 | J7: kg
A8: CHAPA 200x200x4,76 | B8: 0.04 | C8: m2 | D8: 12 | E8: =D8*B8 -> 0.48 | F8: m2 | G8: 37.68 | H8: kg/m2 | I8: =G8*E8 -> 18.0864 | J8: kg
A9: hierro liso Ø 12 | B9: 0.75 | C9: mL | D9: 24 | E9: =B9*D9 -> 18 | F9: mL | G9: 0.888 | H9: kg/mL | I9: =G9*E9 -> 15.984 | J9: kg | O9: =700000/380 -> 1842.1053
O10: =2500000/380 -> 6578.9474
A11: cruces de san andres T2-T2 | O11: =(O10+O9)*1.7 -> 14315.789 | Q11: =(O11-O10-O9)*380 -> 2240000
A12: hierro ANG 2 1/4" x 3/16" | B12: 30.4 | C12: mL | D12: 1.05 | E12: =B12*D12 -> 31.92 | F12: mL | G12: 4.1 | H12: kg/mL | I12: =G12*E12 -> 130.872 | J12: kg
A14: TOTAL anclajes met y cruces de SA T2-T2 (vigas F - Vigas PB)
A16: Insertos para CM1
A18: descripcion | B18: cantidad | D18: unidades | E18: total sup | G18: peso x m2 | I18: total peso | O18: =17*3.5 -> 59.5
A19: CHAPA 150x150x4,76 (CM1) | B19: 0.0225 | C19: m2 | D19: 55 | E19: =D19*B19 -> 1.2375 | F19: m2 | G19: 37.68 | H19: kg/m2 | I19: =G19*E19 -> 46.629 | J19: kg
A20: hierro liso Ø 10 | B20: 1.8 | C20: m2 | D20: 55 | E20: =D20*B20 -> 99 | F20: m2 | G20: 0.617 | H20: kg/m2 | I20: =G20*E20 -> 61.083 | J20: kg
A21: hierro liso Ø 6 | B21: 0.92 | C21: mL | D21: 55 | E21: =B21*D21 -> 50.6 | F21: mL | G21: 0.222 | H21: kg/mL | I21: =G21*E21 -> 11.2332 | J21: kg
A23: TOTAL anclajes insertos para CM1 | L23: kg
A25: Columnas CM200-80-2mm
A27: descripcion | B27: cantidad | D27: unidades | E27: total sup | G27: peso x m2 | I27: total peso
A28: CM planta 1er p (C200/80/25/2,5) | B28: 19 | D28: =3.5*2 -> 7 | E28: =D28*B28 -> 133 | F28: mL | G28: 7.72 | H28: kg/mL | I28: =G28*E28 -> 1026.76 | J28: kg
A30: TOTAL anclajes met en vigas de fundaciones para recibir CM1 | K30: =SUM(I28:I29) -> 1026.76 | L30: kg
A32: Refuerzos DM1
A34: descripcion | B34: cantidad | D34: unidades | E34: total sup | G34: peso x m2 | I34: total peso
A35: hierro liso Ø 12 | B35: 12 | C35: mL | D35: 3 | E35: =B35*D35 -> 36 | F35: mL | G35: 0.888 | H35: kg/mL | I35: =G35*E35 -> 31.968 | J35: kg
A36: CHAPA 300x300x6,4 | B36: =0.3*0.3 -> 0.09 | C36: m2 | D36: 17 | E36: =D36*B36 -> 1.53 | F36: m2 | G36: =25.12*2 -> 50.24 | H36: kg/m2 | I36: =G36*E36 -> 76.8672 | J36: kg
A40: TOTAL anclajes met en vigas de fundaciones para recibir CM1 | K40: =SUM(I34:I39) -> 108.8352 | L40: kg
A42: Vigas VM
A44: descripcion | B44: cantidad | D44: unidades | E44: total sup | G44: peso x m2 | I44: total peso
A45: VM de Contorno (C200/80/25/2,5) | B45: =51*2 -> 102 | C45: mL | D45: 1 | E45: =D45*B45 -> 102 | F45: mL | G45: 7.72 | H45: kg/mL | I45: =G45*E45 -> 787.44 | J45: kg
A46: VM IPN 200 | B46: 14 | C46: mL | D46: 1 | E46: =D46*B46 -> 14 | F46: mL | G46: 26.2 | H46: kg/mL | I46: =G46*E46 -> 366.8 | J46: kg
A47: VM CUBIERTA (C140/50/15/2) | B47: 0 | C47: mL | D47: 1 | E47: =D47*B47 -> 0 | F47: mL | G47: 4.51 | H47: kg/mL | I47: =G47*E47 -> 0 | J47: kg | N47: =12*12 -> 144 | O47: =N47/2 -> 72
A48: planchuela 3/4" *x 1/8" | B48: =B47/0.5*0.1 -> 0 | C48: mL | D48: 1 | E48: =D48*B48 -> 0 | F48: mL | G48: 0.48 | H48: kg/mL | I48: =G48*E48 -> 0 | J48: kg | O48: =8000*O47 -> 576000
A49: hierro angulo 2" x 3/16" | B49: =(20*0.8*3)+31*0.15*2 -> 57.3 | C49: mL | D49: 1 | E49: =D49*B49 -> 57.3 | F49: mL | G49: 3.6 | H49: kg/mL | I49: =G49*E49 -> 206.28 | J49: kg
A51: TOTAL VM1-VM3 | K51: =SUM(I45:I50) -> 1360.52 | L51: kg
A53: CUBIERTA
A55: descripcion | B55: cantidad | D55: unidades | E55: total sup | G55: peso x m2 | I55: total peso
A56: CoC (C140/60/20/2) | B56: 308 | C56: mL | D56: 1 | E56: =D56*B56 -> 308 | F56: mL | G56: =4.51 -> 4.51 | H56: kg/mL | I56: =G56*E56 -> 1389.08 | J56: kg
A57: PRESILLAS CADA 700MM | B57: 2.97 | C57: m2 | D57: 1 | E57: =D57*B57 -> 2.97 | F57: mL | G57: 15.58 | H57: kg/mL | I57: =G57*E57 -> 46.2726 | J57: kg
A58: CHAPA UNION CoC CON VM1/3 | B58: 0.018 | C58: m2 | D58: 123 | E58: =D58*B58 -> 2.214 | F58: mL | G58: 25.12 | H58: kg/m2 | I58: =G58*E58 -> 55.61568 | J58: kg
A60: TOTAL CUBIERTA | L60: kg
...

Sheet Hoja6
O1: =M1/N1 -> #DIV/0!
A2: 1.2 | B2: Partida | C2: Muros bloques de retak 20/50 | D2: M2
B3: Mano de obra | C3: OFICIAL ESPECIALIZADO | D3: hs | E3: 0 | F3: =80000/9+5789 -> 14677.889 | G3: =E3*F3 -> 0
B4: Mano de obra | C4: OFICIAL | D4: hs | E4: 0.8 | F4: =50000/9+5789 -> 11344.556 | G4: =E4*F4 -> 9075.6444
B5: Mano de obra | C5: MEDIO OFICIAL | D5: hs | F5: =45000/9+5789 -> 10789 | G5: =E5*F5 -> 0
B6: Mano de obra | C6: AYUDANTE | D6: hs | E6: 0.7 | F6: =35000/9+5768 -> 9656.8889 | G6: =E6*F6 -> 6759.8222
B7: Mano de obra | C7: AYUDA DE GREMIO ayudante | D7: hs | F7: =F6 -> 9656.8889 | G7: =E7*F7 -> 0
B8: SUBTOTAL MANO DE OBRA (A) | G8: =SUM(G3:G7) -> 15835.467
B9: Material | C9: Pegamento Retak | D9: kg | E9: 6.25 | F9: 600 | G9: =E9*F9 -> 3750
B10: Material | C10: Bloque Retak | D10: u | E10: =8*1.05 -> 8.4 | F10: 6000 | G10: =E10*F10 -> 50400
B11: Material | G11: =E11*F11 -> 0
B12: Material | G12: =E12*F12 -> 0
B13: Material | G13: =E13*F13 -> 0
B14: Material | G14: =E14*F14 -> 0
B15: Material | G15: =E15*F15 -> 0
B16: Material | G16: =E16*F16 -> 0
B17: Material | G17: =E17*F17 -> 0
B18: Material | G18: =E18*F18 -> 0
B19: Material | G19: =E19*F19 -> 0
B20: Material
B21: Material
B22: Material
B23: SUBTOTAL MATERIAL (B) | G23: =SUM(G9:G22) -> 54150
B25: 1 | C25: MANO DE OBRA | D25: TOTAL (A) | G25: =G8 -> 15835.467
B26: 2 | C26: MATERIALES | D26: TOTAL (B) | G26: =G23 -> 54150
B27: 3 | C27: EQUIPOS | D27: TOTAL (C)
B28: 4 | C28: COSTO - COSTO | D28: (1 + 2 + 3) | G28: =SUM(G25:G27) -> 69985.467 | I28: =G28*1.95 -> 136471.66
B29: 5 | C29: GASTOS GENERALES | D29: D% x (4) | E29: 0.25 | G29: =+G28*E29 -> 17496.367
B30: 6 | C30: COSTO - COSTO + GASTOS GENERALES | D30: (4 + 5) | G30: =G29+G28 -> 87481.833
B31: 7 | C31: IMPREVISTOS Y EVENTUALIDADES | D31: E% x (6) | E31: 0.07 | G31: =+G30*E31 -> 6123.7283
B32: 8 | C32: EPP-SEGURIDAD | D32: F% x (6) | E32: 0.05 | G32: =G30*E32 -> 4374.0917
B33: 9 | C33: BENEFICIO | D33: G% x (6) | E33: 0.2 | G33: =G30*E33 -> 17496.367
B34: 10 | C34: COSTO TOTAL DEL TRABAJO | D34: (6 + 7 + 8 + 9) | G34: =G33+G32+G31+G30 -> 115476.02
B35: 11 | C35: COSTO TOTAL DEL TRABAJO SIN MATERIALES | D35: (10 - 1) | G35: =G34-G26 -> 61326.02
B36: 12 | C36: IMPUESTOS (IIBB - GANANCIAS) | D36: V % x (9) | E36: 0.1 | G36: =G34*E36 -> 11547.602
B37: 13 | C37: GANANCIAS | E37: 0 | G37: =G33*E37 -> 0
B39: 16 | C39: PRECIO UNITARIO DE APLICACIÓN SIN MATERIALES | D39: (10 + 12 + 13) | G39: =G35+G36+G37 -> 72873.622 | J39: 1200 | K39: =G39/J39 -> 60.728018
A41: 1.2 | B41: Partida | C41: EXCAVACIONES MANUALES BASES | D41: M3
B42: Mano de obra | C42: OFICIAL ESPECIALIZADO | D42: hs | F42: =F3 -> 14677.889 | G42: =E42*F42 -> 0
B43: Mano de obra | C43: OFICIAL | D43: hs | E43: 0 | F43: =F4 -> 11344.556 | G43: =E43*F43 -> 0
...

Sheet Hoja8
D3: MATERIALES | I3: MANO DE OBRA | N3: MATERIALES | S3: MANO DE OBRA
C4: ESTRUCTURA | D4: hierro barra tn | E4: alambre kg | F4: tablas m2 | G4: tirantes m2 | H4: clavos kg | I4: hora oficial | J4: hora ayudante | M4: ESTRUCTURA | N4: hierro barra tn | O4: alambre kg | P4: tablas m2 | Q4: tirantes m2 | R4: clavos kg | S4: hora oficial | T4: hora ayudante
C5: BASES | D5: 0.06 | E5: 0.25 | I5: 6.15 | J5: 11.3 | M5: BASES | N5: =D5*D14 -> 0.066 | O5: =E5*E14 -> 0.275 | P5: =F5*F14 -> 0 | Q5: =G5*G14 -> 0 | R5: =H5*H14 -> 0 | S5: =I5*I14 -> 6.765 | T5: =J5*J14 -> 12.43
C6: COLUMNAS | D6: 0.085 | E6: 0.6 | F6: 2.5 | G6: 0.36 | H6: 2 | I6: 14.35 | J6: 1.71 | M6: COLUMNAS | N6: =D6*D15 -> 0.0935 | O6: =E6*E15 -> 0.66 | P6: =F6*F15 -> 2.75 | Q6: =G6*G15 -> 0.396 | R6: =H6*H15 -> 2.2 | S6: =I6*I15 -> 15.785 | T6: =J6*J15 -> 1.881
C7: LOSAS Y CORNISAS | D7: 0.08 | E7: 0.6 | F7: 3 | G7: 1 | H7: 1 | I7: 19.15 | J7: 18.05 | M7: LOSAS Y CORNISAS | N7: =D7*D16 -> 0.088 | O7: =E7*E16 -> 0.66 | P7: =F7*F16 -> 3.3 | Q7: =G7*G16 -> 1.1 | R7: =H7*H16 -> 1.1 | S7: =I7*I16 -> 21.065 | T7: =J7*J16 -> 19.855
C8: VIGAS | D8: 0.18 | E8: 0.84 | F8: 3.5 | G8: 1.35 | H8: 1.5 | I8: 32.15 | J8: 18.3 | M8: VIGAS | N8: =D8*D17 -> 0.198 | O8: =E8*E17 -> 0.924 | P8: =F8*F17 -> 3.85 | Q8: =G8*G17 -> 1.485 | R8: =H8*H17 -> 1.65 | S8: =I8*I17 -> 35.365 | T8: =J8*J17 -> 20.13
C9: DINTELES | D9: 0.06 | E9: 0.6 | F9: 3.3 | G9: 0.72 | H9: 1.2 | I9: 37 | J9: 21.9 | M9: DINTELES | N9: =D9*D18 -> 0.066 | O9: =E9*E18 -> 0.66 | P9: =F9*F18 -> 3.63 | Q9: =G9*G18 -> 0.792 | R9: =H9*H18 -> 1.32 | S9: =I9*I18 -> 40.7 | T9: =J9*J18 -> 24.09
C10: TABIQUES | D10: 0.07 | E10: 0.5 | F10: 3.3 | G10: 0.26 | H10: 1.7 | I10: 30 | J10: 25 | M10: TABIQUES | N10: =D10*D19 -> 0.077 | O10: =E10*E19 -> 0.55 | P10: =F10*F19 -> 3.63 | Q10: =G10*G19 -> 0.286 | R10: =H10*H19 -> 1.87 | S10: =I10*I19 -> 33 | T10: =J10*J19 -> 27.5
C11: ENCADENADOS | D11: 0.05 | E11: 0.4 | F11: 2.5 | H11: 1.1 | I11: 25 | J11: 12.5 | M11: ENCADENADOS | N11: =D11*D20 -> 0.0525 | O11: =E11*E20 -> 0.42 | P11: =F11*F20 -> 2.625 | Q11: =G11*G20 -> 0 | R11: =H11*H20 -> 1.155 | S11: =I11*I20 -> 26.25 | T11: =J11*J20 -> 13.125
C12: ESCALERAS | D12: 0.055 | E12: 0.45 | F12: 2 | G12: 0.78 | H12: 1.7 | I12: 39.5 | J12: 22.5 | M12: =C12 -> ESCALERAS | N12: =D12*D21 -> 0.055 | O12: =E12*E21 -> 0.45 | P12: =F12*F21 -> 2 | Q12: =G12*G21 -> 0.78 | R12: =H12*H21 -> 1.7 | S12: =I12*I21 -> 39.5 | T12: =J12*J21 -> 22.5
D14: 1.1 | E14: =D14 -> 1.1 | F14: =E14 -> 1.1 | G14: =F14 -> 1.1 | H14: =G14 -> 1.1 | I14: =H14 -> 1.1 | J14: =I14 -> 1.1
D15: 1.1 | E15: =D15 -> 1.1 | F15: =E15 -> 1.1 | G15: =F15 -> 1.1 | H15: =G15 -> 1.1 | I15: =H15 -> 1.1 | J15: =I15 -> 1.1
D16: 1.1 | E16: =D16 -> 1.1 | F16: =E16 -> 1.1 | G16: =F16 -> 1.1 | H16: =G16 -> 1.1 | I16: =H16 -> 1.1 | J16: =I16 -> 1.1
D17: 1.1 | E17: =D17 -> 1.1 | F17: =E17 -> 1.1 | G17: =F17 -> 1.1 | H17: =G17 -> 1.1 | I17: =H17 -> 1.1 | J17: =I17 -> 1.1
D18: 1.1 | E18: =D18 -> 1.1 | F18: =E18 -> 1.1 | G18: =F18 -> 1.1 | H18: =G18 -> 1.1 | I18: =H18 -> 1.1 | J18: =I18 -> 1.1
D19: 1.1 | E19: =D19 -> 1.1 | F19: =E19 -> 1.1 | G19: =F19 -> 1.1 | H19: =G19 -> 1.1 | I19: =H19 -> 1.1 | J19: =I19 -> 1.1
D20: 1.05 | E20: =D20 -> 1.05 | F20: =E20 -> 1.05 | G20: =F20 -> 1.05 | H20: =G20 -> 1.05 | I20: =H20 -> 1.05 | J20: =I20 -> 1.05
D21: 1 | E21: =D21 -> 1 | F21: =E21 -> 1 | G21: =F21 -> 1 | H21: =G21 -> 1 | I21: =H21 -> 1 | J21: =I21 -> 1

Sheet COMP Y PRES 2
A1: EMPRESA CONSTRUCTORA GRUPO SL SAS
A2: San Carlos de Bariloche, 23 de MARZO de 2025
A3: De nuestra mayor consideración: Tenemos el agrado de elevar para vuestra consideración la siguiente Cotización sobre: Construcción Vivienda unifamiliar - Barrio Belgrano - SAN CARLOS DE BARILOCHE
A5: Monto Total de la Obra expresada en dolares: .................................................................... | F5: =F29 -> 25154813
B6: SON DOLARES CUARENTA Y SIETE MIL SEISCIENTOS CUARENTA Y UNO CON 41/100
A9: Valor expreado en dolares blue. - Consideraciones Generales Otros detalles no especificados en la documentación y que fuera objeto de análisis para el cálculo de la presente cotización, a definir y cotizar. - Obras a desarrollarse en Días hábiles APTOS: se consideran días de ejecución semanal en horario de 9hs. a 17hs. (a criterio técnico de nuestro personal, a coordinar), en condiciones normales de trabajo SEGURO a la Intemperie; otras “a nuestro exclusivo criterio”. - Todos los servicios necesarios para la realización de las obras en el sector OBRA (agua, electricidad, sanitarios), se consideran provistos por el cliente a pie de obra. - Nuestro personal calificado (por rubros) prestara sus servicios en obra, con máquinas y herramientas, EPP e infraestructura apta para las distintas tareas a realizar, a nuestro criterio.
A12: ITEM | B12: DESCRIPCION | C12: UND. | D12: CANT. | E12: P. UNITARIO | F12: P. TOTAL ITEM | I12: 1.3 | L12: 1360
A13: 1 - TAREAS PRELIMINARES
A14: 1.1 | B14: Obrador y Baño quimico (no se cotiza) | C14: Gl. | D14: 3 | E14: 269.16 | F14: =E14*D14 -> 807.48
A15: 1.2 | B15: Cerco de Obra | C15: Gl. | D15: 1 | E15: 1230 | F15: =E15*D15 -> 1230
D16: SUBTOTAL ITEM 1.- | F16: =SUM(F14:F15) -> 2037.48
A17: 2 - ESTRUCTURAS, EXCAVACIONES, HORMIGON FUNDACIONES, PLATEA CON VIGAS. | K17: =SUM(J18:J21) -> 102.1015
A18: 2.1 | B18: Demolicion de mamposterias, traslados de puertas, acarreo de demoliciones a contenedores (incluye contratacion de contenedores) | C18: Gl. | D18: =(55.54*3)*2.5+25*3 -> 491.55 | E18: =Hoja6!G429 -> 51093.553 | F18: =E18*D18 -> 25115036 | H18: 5.96 | I18: 1.85 | J18: =I18*H18 -> 11.026 | L18: =#REF! -> #REF! | M18: =L18*J18 -> #REF!
A19: 2.2 | B19: Bases aisladas (a 1m de profundidad) | C19: Gl. | D19: 6 | E19: =Hoja6!K195 -> 477.15307 | F19: =E19*D19 -> 2862.9184
A20: 2.3 | B20: Troncos de Columnas y columnas | C20: Gl. | D20: 4.59 | E20: =Hoja6!K234 -> 548.63919 | F20: =E20*D20 -> 2518.2539
A21: 2.4 | B21: Vigas -3,24, +/-0,00 y +4,2 | C21: Gl. | D21: 11.88 | E21: =Hoja6!K312 -> 1331.3828 | F21: =E21*D21 -> 15816.828 | H21: 49.23 | I21: =I18 -> 1.85 | J21: =I21*H21 -> 91.0755 | L21: =L18 -> #REF! | M21: =L21*J21 -> #REF!
A22: 2.5 | B22: Losas -3,24 y +/-0,00 | C22: Gl. | D22: 13.68 | E22: =Hoja6!K351 -> 927.4036 | F22: =E22*D22 -> 12686.881 | H22: 52.1 | I22: 1.45 | J22: =I22*H22 -> 75.545 | L22: =L21 -> #REF! | M22: =L22*J22 -> #REF!
A23: 2.6 | B23: Escaleras | C23: Gl. | D23: 2.62 | E23: =Hoja6!K390 -> 1222.3569 | F23: =E23*D23 -> 3202.5751
D24: SUBTOTAL ITEM 2.- | F24: =SUM(F18:F23) -> 25152123 | G24: =F24+F16 -> 25154161 | BC24: =BC21 -> 0
A25: 3 - VARIOS | J25: =37000/60 -> 616.66667 | BC25: =#REF! -> #REF!
A26: 3.1 | B26: Limpieza periodica y final de obra | C26: Gl. | D26: 1 | E26: 652.1 | F26: =E26*D26 -> 652.1 | H26: 1360 | I26: =F26*H26 -> 886856 | L26: 11 | M26: 1.95 | BC26: =#REF! -> #REF!
D27: SUBTOTAL ITEM 10.- | F27: =SUM(F26:F26) -> 652.1 | BC27: =#REF! -> #REF!
A29: TOTAL PRESUPUESTO | F29: =F27+F24+F16 -> 25154813 | G29: =F29/180 -> 139748.96 | H29: 1300 | I29: =H29*F29 -> 3.2701257e+10 | J29: =F29/60 -> 419246.88
A32: En la presente cotizacion no se incluyen valores de IVA.
A33: Los valores expresados en la presente cotizacion, de mano de obra, estan expresados en dólares BLUE
A34: La presente cotización tiene validez por 20 días.
A35: Forma de pago: 20% de anticipo y certificaciones quincenales según avance de obra.
AO46: PB
AO47: 1.5
AO48: 1.5
AO49: 0.8
AO50: 1.3
AO51: 3.2
AO52: 3.4
AO53: 1.3 | AP53: 0.8 | AQ53: 2.1 | AR53: 3 | AS53: =AP53*AQ53*AR53 -> 5.04
AO54: 2.55 | AP54: 0.9 | AQ54: 2.1 | AR54: 1 | AS54: =AP54*AQ54*AR54 -> 1.89
AO55: 2.45 | AP55: 2.3 | AQ55: 1.7 | AR55: 1 | AS55: =AP55*AQ55*AR55 -> 3.91
AO56: 3.8 | AP56: 0.9 | AQ56: 1.5 | AR56: 2 | AS56: =AP56*AQ56*AR56 -> 2.7
AO57: 0.7 | AP57: 2.3 | AQ57: 1.9 | AR57: 1 | AS57: =AP57*AQ57*AR57 -> 4.37
AO58: 3.5
...

Sheet Hoja4
N1: =SUM(L3:R3) -> 2642901.5
I2: MANO DE OBRA | L2: GASTOS GENERALES 12% | M2: IMPREVISTOS Y EVENTUALIDADES 8% | N2: EPP y SEGURIDAD 5% | O2: BENEFICIO 15% | P2: INGRESOS BRUTOS 3% | Q2: GANANCIAS 35% | R2: INSUMIBLES | T2: Mano de Obra | Z2: Materiales | AA2: Gastos Generales | AB2: Imprev y event | AC2: EEP Seguridad | AD2: Beneficio | AE2: IIBB | AF2: Ganancias
I3: =SUM(I4:I1048576) -> #REF! | J3: =SUM(I3,L3,M3,N3,O3,P3,Q3,R3) -> #REF! | L3: =SUM(L4:L1048576) -> 514069.88 | M3: =SUM(M4:M1048576) -> 222708.05 | N3: =SUM(N4:N1048576) -> 133363.09 | O3: =SUM(O4:O1048576) -> 800049.31 | P3: =SUM(P4:P1048576) -> 211098.13 | Q3: =SUM(Q4:Q1048576) -> 209788.56 | R3: =SUM(R4:R1048576) -> 551824.5 | T3: =SUM(T4:T1048576) -> 401424.64 | V3: =SUM(V10:V87) -> 161189.58 | Y3: =SUM(Y10:Y87) -> 152004.91 | Z3: =SUM(Z4:Z1048576) -> 177569.8 | AA3: =SUM(AA4:AA1048576) -> 84229.394 | AB3: =SUM(AB4:AB1048576) -> 36528.667 | AC3: =SUM(AC4:AC1048576) -> 22255.782 | AD3: =SUM(AD4:AD1048576) -> 132120.27 | AE3: =SUM(AE4:AE1048576) -> 35779.344 | AF3: =SUM(AF4:AF1048576) -> 35557.383 | AI3: 4000 | AJ3: 1 | AK3: =AI3*AJ3 -> 4000 | AM3: 250 | AN3: 4 | AO3: =AN3*AM3*AJ3 -> 1000 | AQ3: =AO3+AK3 -> 5000
A4: 1.1 | B4: Partida | C4: CONTRAPISOS | D4: M2 | AI4: 3500 | AJ4: 2 | AK4: =AI4*AJ4 -> 7000 | AM4: 180 | AN4: 4 | AO4: =AN4*AM4*AJ4 -> 1440 | AQ4: =AO4+AK4 -> 8440
B5: Mano de obra | C5: OFICIAL ESPECIALIZADO | D5: hs | F5: =(50000+12500)/9 -> 6944.4444 | G5: =E5*F5 -> 0 | AI5: 2500 | AJ5: 4 | AK5: =AI5*AJ5 -> 10000 | AM5: 180 | AN5: 4 | AO5: =AN5*AM5*AJ5 -> 2880 | AQ5: =AO5+AK5 -> 12880
B6: Mano de obra | C6: OFICIAL | D6: hs | E6: 1.1 | F6: =(45000+12500)/9 -> 6388.8889 | G6: =E6*F6 -> 7027.7778
B7: Mano de obra | C7: MEDIO OFICIAL | D7: hs | F7: =(40000+12500)/9 -> 5833.3333 | G7: =E7*F7 -> 0 | AK7: =SUM(AK3:AK6) -> 21000 | AO7: =SUM(AO3:AO6) -> 5320 | AQ7: =SUM(AQ3:AQ6) -> 26320 | AR7: =AQ7*50 -> 1316000
B8: Mano de obra | C8: AYUDANTE | D8: hs | E8: 1.05 | F8: =(35000+12500)/9 -> 5277.7778 | G8: =E8*F8 -> 5541.6667
B9: Mano de obra | C9: AYUDA DE GREMIO ayudante | D9: hs | F9: =F8 -> 5277.7778 | G9: =E9*F9 -> 0
B10: SUBTOTAL MANO DE OBRA (A) | G10: =SUM(G5:G9) -> 12569.444 | I10: =G10*K10 -> 117021.53 | K10: =K31 -> 9.31 | T10: =G10 -> 12569.444 | U10: 9.31 | V10: =U10*T10 -> 117021.53
B11: Material | C11: Cemento común (50kg) | D11: kg | E11: =38*0.6 -> 22.8 | F11: =13000/50 -> 260 | G11: =E11*F11 -> 5928
B12: Material | C12: piedra | D12: m3 | E12: =0.08*0.6 -> 0.048 | F12: =250000/5 -> 50000 | G12: =E12*F12 -> 2400
B13: Material | C13: Arena lavada | D13: m3 | E13: =0.08*0.6 -> 0.048 | F13: 50000 | G13: =E13*F13 -> 2400
B14: Material | C14: hierro | D14: kg | E14: 1 | F14: 1800 | G14: =E14*F14 -> 1800 | J14: =0.08*1*1 -> 0.08
B15: Material | C15: Hidrófugo en pasta | D15: kg | E15: 2 | G15: =E15*F15 -> 0 | J15: =J14*6*50 -> 24 | R15: =(G15+G14+G13+G12)*K10 -> 61446
B16: Material | C16: Poliestireno expandido 20 mm | D16: m2 | E16: 1.05 | G16: =E16*F16 -> 0
B17: Material | C17: Polietileno 200 micrones | D17: m2 | E17: 1.05 | G17: =E17*F17 -> 0
B18: Material | G18: =E18*F18 -> 0
B19: Material | G19: =E19*F19 -> 0
B20: Material | G20: =E20*F20 -> 0
B21: Material | G21: =E21*F21 -> 0
B22: Material | G22: =E22*F22 -> 0
B23: Material | G23: =E23*F23 -> 0
B24: Material | G24: =E24*F24 -> 0
B25: SUBTOTAL MATERIAL (B) | G25: =SUM(G11:G24) -> 12528 | Z25: =G25 -> 12528
B27: 1 | C27: MATERIALES | D27: TOTAL (A) | G27: =G10 -> 12569.444
B28: 2 | C28: MANO DE OBRA | D28: TOTAL (B) | G28: =G25 -> 12528
B29: 3 | C29: EQUIPOS | D29: TOTAL (C)
B30: 4 | C30: COSTO - COSTO | D30: (1 + 2 + 3) | G30: =SUM(G27:G29) -> 25097.444
B31: 5 | C31: GASTOS GENERALES | D31: D% x (4) | E31: 0.2 | G31: =+G30*E31 -> 5019.4889 | J31: =G31 -> 5019.4889 | K31: 9.31 | L31: =K31*J31 -> 46731.442 | AA31: =G31 -> 5019.4889
B32: 6 | C32: COSTO - COSTO + GASTOS GENERALES | D32: (4 + 5) | G32: =G31+G30 -> 30116.933
B33: 7 | C33: IMPREVISTOS Y EVENTUALIDADES | D33: E% x (6) | E33: 0.07 | G33: =+G32*E33 -> 2108.1853 | J33: =G33 -> 2108.1853 | K33: 9.31 | M33: =K33*J33 -> 19627.205 | AB33: =G33 -> 2108.1853
B34: 8 | C34: EPP-SEGURIDAD | D34: F% x (6) | E34: 0.02 | G34: =G32*E34 -> 602.33867 | J34: =G34 -> 602.33867 | K34: 9.31 | N34: =K34*J34 -> 5607.773 | AC34: =G34 -> 602.33867
B35: 9 | C35: BENEFICIO | D35: G% x (6) | E35: 0.2 | G35: =G32*E35 -> 6023.3867 | J35: =G35 -> 6023.3867 | K35: 9.31 | O35: =K35*J35 -> 56077.73 | W35: =G35+G34+G33+G31 -> 13753.4 | X35: 9.31 | Y35: =X35*W35 -> 128044.15 | AD35: =G35 -> 6023.3867
B36: 10 | C36: COSTO TOTAL DEL TRABAJO | D36: (6 + 7 + 8 + 9) | G36: =G35+G34+G33+G32 -> 38850.844
B37: 11 | C37: COSTO TOTAL DEL TRABAJO SIN MATERIALES | D37: (10 - 1) | G37: =G36-G28 -> 26322.844
B38: 12 | C38: IMPUESTOS (IIBB - GANANCIAS) | D38: V % x (9) | E38: 0 | G38: =G36*E38 -> 0 | J38: =G38 -> 0 | K38: 9.31 | P38: =K38*J38 -> 0 | AE38: =G38 -> 0
B39: 13 | C39: GANANCIAS | E39: 0 | G39: =G35*E39 -> 0 | J39: =G39 -> 0 | K39: 9.31 | Q39: =K39*J39 -> 0 | AF39: =G39 -> 0
B41: 14 | C41: PRECIO UNITARIO DE APLICACIÓN CON MATERIALES | D41: (10 + 12 + 13) | G41: =G36+G38+G39 -> 38850.844
B42: 15 | C42: PRECIO UNITARIO DE APLICACIÓN CON MATERIALES + IVA | D42: (11 + 12 + 13 + IVA) | G42: =(G36+G38+G39)*1.21 -> 47009.521 | I42: =G27*2 -> 25138.889
...

Sheet Hoja5
I5: EN DOLARES
B6: 7500 | C6: 4 | D6: =B6*C6 -> 30000 | E6: 1 | F6: 350000 | G6: =F6*E6 -> 350000 | I6: =B6/289 -> 25.951557 | J6: 4 | K6: =J6*I6 -> 103.80623 | L6: 1 | M6: =F6/289 -> 1211.0727 | N6: =M6*L6 -> 1211.0727 | O6: maquina
B7: 8000 | C7: 3 | D7: =B7*C7 -> 24000 | E7: 1 | F7: 70000 | G7: =F7*E7 -> 70000 | I7: =B7/289 -> 27.681661 | J7: 3 | K7: =J7*I7 -> 83.044983 | L7: 1 | M7: =70000/289 -> 242.21453 | N7: =M7*L7 -> 242.21453 | O7: camion
B8: 4300 | C8: 75 | D8: =B8*C8 -> 322500 | E8: 1.75 | F8: =E8*B8 -> 7525 | G8: =F8*C8 -> 564375 | I8: =B8/289 -> 14.878893 | J8: 75 | K8: =J8*I8 -> 1115.917 | L8: 1.7 | M8: =L8*I8 -> 25.294118 | N8: =M8*J8 -> 1897.0588 | O8: cerco
B9: 785 | C9: 78 | D9: =B9*C9 -> 61230 | E9: =E8 -> 1.75 | F9: =E9*B9 -> 1373.75 | G9: =F9*C9 -> 107152.5 | I9: =B9/289 -> 2.716263 | J9: 203 | K9: =J9*I9 -> 551.40138 | L9: =L8 -> 1.7 | M9: =L9*I9 -> 4.6176471 | N9: =M9*J9 -> 937.38235 | O9: replanteo | P9: =N9*306 -> 286839
B10: 5130 | C10: 3 | D10: =B10*C10 -> 15390 | E10: =E9 -> 1.75 | F10: =E10*B10 -> 8977.5 | G10: =F10*C10 -> 26932.5 | I10: =B10/289 -> 17.750865 | J10: 3 | K10: =J10*I10 -> 53.252595 | L10: =L9 -> 1.7 | M10: =L10*I10 -> 30.176471 | N10: =M10*J10 -> 90.529412 | O10: excavacion manual
B11: 5137 | C11: 1.7 | D11: =B11*C11 -> 8732.9 | E11: =E10 -> 1.75 | F11: =E11*B11 -> 8989.75 | G11: =F11*C11 -> 15282.575 | I11: =B11/289 -> 17.775087 | J11: 1.7 | K11: =J11*I11 -> 30.217647 | L11: =L10 -> 1.7 | M11: =L11*I11 -> 30.217647 | N11: =M11*J11 -> 51.37 | O11: excavacion manual
B12: 3960 | C12: 110 | D12: =B12*C12 -> 435600 | E12: =E11 -> 1.75 | F12: =E12*B12 -> 6930 | G12: =F12*C12 -> 762300 | I12: =B12/289 -> 13.702422 | J12: 110 | K12: =J12*I12 -> 1507.2664 | L12: =L11 -> 1.7 | M12: =L12*I12 -> 23.294118 | N12: =M12*J12 -> 2562.3529 | O12: mamposteria
B13: 3460 | C13: 51.1 | D13: =B13*C13 -> 176806 | E13: =E12 -> 1.75 | F13: =E13*B13 -> 6055 | G13: =F13*C13 -> 309410.5 | I13: =B13/289 -> 11.972318 | J13: 51.1 | K13: =J13*I13 -> 611.78547 | L13: =L12 -> 1.7 | M13: =L13*I13 -> 20.352941 | N13: =M13*J13 -> 1040.0353 | O13: encadenados
B14: 4660 | C14: 40.5 | D14: =B14*C14 -> 188730 | E14: =E13 -> 1.75 | F14: =E14*B14 -> 8155 | G14: =F14*C14 -> 330277.5 | I14: =B14/289 -> 16.124567 | J14: 40.5 | K14: =J14*I14 -> 653.04498 | L14: =L13 -> 1.7 | M14: =L14*I14 -> 27.411765 | N14: =M14*J14 -> 1110.1765 | O14: columnas
B15: 7850 | C15: 45 | D15: =B15*C15 -> 353250 | E15: =E14 -> 1.75 | F15: =E15*B15 -> 13737.5 | G15: =F15*C15 -> 618187.5 | I15: =B15/289 -> 27.16263 | J15: 45 | K15: =J15*I15 -> 1222.3183 | L15: =L14 -> 1.7 | M15: =L15*I15 -> 46.176471 | N15: =M15*J15 -> 2077.9412 | O15: plateas
B16: 650 | C16: 90 | D16: =B16*C16 -> 58500 | E16: =E15 -> 1.75 | F16: =E16*B16 -> 1137.5 | G16: =F16*C16 -> 102375 | I16: =B16/289 -> 2.2491349 | J16: 90 | K16: =J16*I16 -> 202.42215 | L16: =L15 -> 1.7 | M16: =L16*I16 -> 3.8235294 | N16: =M16*J16 -> 344.11765 | O16: azotado
B17: 2930 | C17: 60 | D17: =B17*C17 -> 175800 | E17: =E16 -> 1.75 | F17: =E17*B17 -> 5127.5 | G17: =F17*C17 -> 307650 | I17: =B17/289 -> 10.138408 | J17: 60 | K17: =J17*I17 -> 608.3045 | L17: =L16 -> 1.7 | M17: =L17*I17 -> 17.235294 | N17: =M17*J17 -> 1034.1176 | O17: membranas
B18: 6300 | C18: 30 | D18: =B18*C18 -> 189000 | E18: =E17 -> 1.75 | F18: =E18*B18 -> 11025 | G18: =F18*C18 -> 330750 | I18: =B18/289 -> 21.799308 | J18: 30 | K18: =J18*I18 -> 653.97924 | L18: =L17 -> 1.7 | M18: =L18*I18 -> 37.058824 | N18: =M18*J18 -> 1111.7647 | O18: viguetas
D20: =SUM(D6:D19) -> 2039538.9 | G20: =SUM(G6:G19) -> 3894693.1 | K20: =SUM(K6:K19) -> 7396.7609 | N20: =SUM(N6:N19) -> 13710.134
M22: =N20-K20 -> 6313.3728

Sheet Hoja1
A1: estructura sobre planta baja | E1: peso | I1: metro cuadrado de pared planta alta
A2: vigas | D2: m/l | P2: PRECIO APROX
A3: 2 | B3: 140 | C3: 7 | D3: =C3*A3 -> 14 | E3: 4.51 | F3: =E3*D3 -> 63.14 | I3: pgc 100 | J3: 6290 | K3: =J3*1.2 -> 7548 | N3: PAREDES EXTERIORES: PGC 100; PGU 100; PLACAS OSB 11mm (dobles); TYBEK; PLACA YESO 12,5mm; CELULOSA 100mm; TORNILLERIAS | P3: =K3+K4+K7+K8+K9+K12+K15 -> 28916.556
A4: 4 | B4: 140 | C4: 6.9 | D4: =C4*A4 -> 27.6 | E4: 4.51 | F4: =E4*D4 -> 124.476 | I4: pgu 100 | J4: 1590 | K4: =J4*1.2 -> 1908
A5: 4 | B5: 140 | C5: 2.6 | D5: =C5*A5 -> 10.4 | E5: 4.51 | F5: =E5*D5 -> 46.904 | I5: mont 70 | J5: 897.82 | K5: =J5*1.2 -> 1077.384
A6: 2 | B6: 140 | C6: 4.5 | D6: =C6*A6 -> 9 | E6: 4.51 | F6: =E6*D6 -> 40.59 | I6: solera 70 | J6: 401.5 | K6: =J6*1.2 -> 481.8
A7: 2 | B7: 140 | C7: 8.3 | D7: =C7*A7 -> 16.6 | E7: 4.51 | F7: =E7*D7 -> 74.866 | I7: placa osb | J7: 5623.13 | K7: =J7*1.2 -> 6747.756
I8: placa yeso | J8: 1840 | K8: =J8*1.2 -> 2208
A9: 2 | B9: 200 | C9: 4.5 | D9: =C9*A9 -> 9 | E9: 7.72 | F9: =E9*D9 -> 69.48 | I9: tybek | J9: 254 | K9: =J9*1.2 -> 304.8 | N9: PAREDES INTERIORES: PGC 100; PGU 100; PLACAS OSB 11mm (dobles); PLACA YESO 12,5mm (dobles); CELULOSA 100mm; TORNILLERIAS | P9: =+K3+K4+K7+K8+K12+J15 -> 27611.756
A10: 3 | B10: 200 | C10: 4.4 | D10: =C10*A10 -> 13.2 | E10: 7.72 | F10: =E10*D10 -> 101.904 | I10: eps 50 | J10: 3590 | K10: =J10*1.2 -> 4308
I11: alf 2"x2" | J11: 795 | K11: =J11*1.2 -> 954
A12: columnas | I12: celulosa 100 | J12: 3500 | K12: =J12*1.2 -> 4200
A13: 7 | B13: 200 | C13: 2.5 | D13: =C13*A13 -> 17.5 | E13: 7.72 | F13: =E13*D13 -> 135.1 | I13: chapa | J13: 5470 | K13: =J13*1.2 -> 6564
A14: 18 | B14: 140 | C14: 2.5 | D14: =C14*A14 -> 45 | E14: 4.51 | F14: =E14*D14 -> 202.95 | J14: =SUM(J3:J13) -> 30251.45 | K14: m2 | L14: =J12+J9+J8+J7+J6+J5+J4+J3 -> 20396.45
I15: tornilleria | J15: 5000 | K15: =J15*1.2 -> 6000 | N15: REVESTIMIENTOS EXTERIORES: EPS 50mm; ALFAJIAS 2"X2"; CHAPA SINUSOIDAL; TORNILLERIAS | P15: =+K11+K10+K13+J15-1500 -> 15326
A16: plancuelas de 1/4" | J16: =SUM(J14:J15) -> 35251.45 | K16: =SUM(K3:K4,K7,K8,K9,K11,K12,K13,K15) -> 36434.556
C17: m2 | D17: m2
A18: 12 | C18: =(0.3*0.3)+(0.1*0.2) -> 0.11 | D18: =C18*A18 -> 1.32 | E18: 49.85 | F18: =E18*D18 -> 65.802 | I18: =J18*1.25 -> 27821.413 | J18: =J3+J4+J7+J9+J12+J15 -> 22257.13 | L18: 2851400.4
J19: 310.55 | L19: 2356629.3
A20: estructura sobre planta alta | J20: =J19*J18 -> 6911951.7 | L20: =L18-L19 -> 494771.14
A21: vigas | L21: =L20/2 -> 247385.57 | M21: =L18-L21 -> 2604014.8 | N21: =M21/393 -> 6625.9919
A22: 1 | B22: 160 | C22: 22.15 | D22: =C22*A22 -> 22.15 | E22: 4.82 | F22: =E22*D22 -> 106.763 | M22: 450000 | N22: maquina
M23: 150000 | N23: postes y alambrados
M24: 189000 | N24: losetas
A25: columnas | M25: 26988 | N25: replanteos
M26: 15390 | N26: excavacion manual vigas
A27: 5 | B27: 160 | C27: 2.3 | D27: =C27*A27 -> 11.5 | E27: 4.82 | F27: =E27*D27 -> 55.43 | M27: 10274 | N27: excavacion manual bases
M28: 435000 | N28: mamposteria
A29: plancuelas de 3/16" | M29: 136000 | N29: vigas 20/40
C30: m2 o m/l | M30: 183726 | N30: encadenados
A31: 7 | C31: =0.2*0.2 -> 0.04 | D31: =C31*A31 -> 0.28 | E31: 37.7 | F31: =E31*D31 -> 10.556 | M31: 137700 | N31: columnas
A32: 7 | C32: 1.6 | D32: =C32*A32 -> 11.2 | E32: 0.888 | F32: =E32*D32 -> 9.9456 | M32: 56250 | N32: cerecita
F33: =SUM(F22:F32) -> 182.6946 | H33: 1.95 | J33: =H33*F33 -> 356.25447 | K33: =J33*180 -> 64125.805 | M33: 205100 | N33: membrana
M34: 432000 | N34: plateas
L35: TOTAL | M35: =SUM(M22:M34) -> 2427428 | N35: 290 | O35: =M35/N35 -> 8370.4414
A36: cabriada de madera | M36: =M35*1.8 -> 4369370.4 | O36: =O35/78 -> 107.31335
F38: 58500 | M38: =M36-M35 -> 1941942.4
K39: =F38+K33 -> 122625.8

Sheet COMPUTO
A1: GONZALEZ GABRIEL ALEJANDRO - M.M.O. MAT: B1-1683/3 - LOSA SEBASTIAN - ARQ. MAT: 2066/3
A2: San Carlos de Bariloche, 22 de Noviembre de 2022
A3: De nuestra mayor consideración: Tenemos el agrado de elevar para vuestra consideración la siguiente Cotización sobre: Construcción Vivienda Unifamiliar - BARRANCAS DE DINA HUAPI - LOTE 350
A4: Provisión de toda la mano de obra necesaria para la completa construcción y culminación de trabajos estructurales de Hormigon Armado; Bases, Troncos de columnas, Vigas de Fundaciones, Plateas de Fundaciones, Columnas S/PB, Vigas S/PB, Losa S/PB, columnas S/PA, Vigas S/PA, Losa S/PA, según lineamientos de la documentación entregadas por Ustedes.
A5: Monto Total de la Obra expresada en pesos: ..................................................... | F5: =F60 -> #REF! | I5: =F60 -> #REF! | J5: =I5/110/80 -> #REF!
B6: SON PESOS NOVECIENTOS OCHENTA Y SIETE MIL NOVECIENTOS TREINTA Y SIETE CON 19/100 | I6: =F68 -> #REF!
A7: Valor expreado en dolares blue. - Consideraciones Generales Otros detalles no especificados en la documentación y que fuera objeto de análisis para el cálculo de la presente cotización, a definir y cotizar. - Obras a desarrollarse en Días hábiles APTOS: se consideran días de ejecución semanal en horario de 9hs. a 17hs. (a criterio técnico de nuestro personal, a coordinar), en condiciones normales de trabajo SEGURO a la Intemperie; otras “a nuestro exclusivo criterio”. - Todos los servicios necesarios para la realización de las obras en el sector OBRA (agua, electricidad, sanitarios), se consideran provistos por el cliente a pie de obra. - Nuestro personal calificado (por rubros) prestara sus servicios en obra, con máquinas y herramientas, EPP e infraestructura apta para las distintas tareas a realizar, a nuestro criterio.
A8: En la presente cotización no se incluyen: • Movimientos de suelos a Maquina. • Aportes de suelos. • Materiales. • Insumibles. • Maderas para encofrados.
A9: ITEM | B9: DESCRIPCION | C9: UND. | D9: CANT. | E9: P. UNITARIO | F9: P. TOTAL ITEM
A10: 1 - TAREAS PRELIMINARES
A11: 1.1 | B11: Replanteo | C11: Gl. | D11: 1 | E11: =Hoja5!N9*306 -> 286839 | F11: =E11*D11 -> 286839 | G11: 318 | H11: =F11/G11 -> 902.00943
A12: 1.2 | B12: Obrador y Baño quimico | C12: MES | D12: 3 | E12: =(22000*1+15000) -> 37000 | F12: =E12*D12+(65000/308) -> 111211.04 | G12: =G11 -> 318 | H12: =F12*G12 -> 35365110
A13: 1.3 | B13: Cerco de obra (NO SE COTIZA) | G13: =G12 -> 318
D14: SUBTOTAL ITEM 1.- | F14: =SUM(F11:F13) -> 398050.04 | G14: =G13 -> 318 | I14: =F14 -> 398050.04
A15: 2 - EXCAVACIONES, HORMIGON FUNDACIONES, PLATEAS, COLUMNAS Y VIGAS. | G15: =G14 -> 318
A16: 2.1 | B16: Movimientos de suelos y excavaciones manuales para bases y vigas. Relleno y compactación de suelos seleccionados | C16: Gl. | D16: 1 | E16: =Hoja6!K78 -> 148.25135 | F16: =E16*D16 -> 148.25135 | G16: =G15 -> 318 | H16: =F16*G16 -> 47143.93 | I16: =F16*0.8 -> 118.60108
A17: 2.2 | B17: Bases aisladas de fundacion | C17: M3 | D17: =Hoja6!J195 -> 1200 | E17: =Hoja6!G195 -> 572583.68 | F17: =E17*D17 -> 6.8710042e+08 | G17: =G16 -> 318 | H17: =F17*G17 -> 2.1849793e+11
A18: 2.3 | B18: Troncos de Columnas | C18: M3 | D18: =Hoja6!J234 -> 1200 | E18: =Hoja6!G234 -> 658367.02 | F18: =E18*D18 -> 7.9004043e+08 | G18: =G17 -> 318 | H18: =F18*G18 -> 2.5123286e+11
A19: 2.4 | B19: Vigas, Contrapisos y Losas de fundaciones niveles -0,10 y -0,20 | C19: M3 | D19: 31.02 | E19: =Hoja6!#REF!*305 -> #REF! | F19: =E19*D19 -> #REF! | G19: =G18 -> 318 | H19: =F19*G19 -> #REF! | I19: =F19/203 -> #REF!
A20: 2.5 | B20: Columnas y C/E sobre Planta Baja y Alta | C20: M3 | D20: =Hoja6!J273 -> 1200 | E20: =Hoja6!G273 -> 658367.02 | F20: =E20*D20 -> 7.9004043e+08 | G20: =G19 -> 318 | H20: =F20*G20 -> 2.5123286e+11
A21: 2.6 | B21: Vigas y encadenados | C21: M3 | D21: =Hoja6!J312 -> 1200 | E21: =Hoja6!G312 -> 1597659.4 | F21: =E21*D21 -> 1.9171913e+09 | G21: =G20 -> 318 | H21: =F21*G21 -> 6.0966683e+11
A22: 2.7 | B22: Losas sobre Planta Baja y Alta | C22: M3 | D22: =Hoja6!J351 -> 1200 | E22: =Hoja6!G351 -> 1112884.3 | F22: =E22*D22 -> 1.3354612e+09 | G22: =G21 -> 318 | H22: =F22*G22 -> 4.2467666e+11
D23: SUBTOTAL ITEM 2.- | F23: =SUM(F16:F22) -> #REF! | I23: =SUM(H16:H17) -> 2.1849798e+11
A24: 3 - MAMPOSTERIAS, REVOQUES Y DRENAJES
A25: 3.1 | B25: Muros de contencion en bloques hormigon armado, azotados hidrofugos verticales, pintura con emulsion asfaltica, colocacion de membrana asfaltica, aislaciones de EPS y drenajes perimetrales. | C25: Gl. | E25: =Hoja5!N12+Hoja5!N16+Hoja5!N17+650 -> 4590.5882 | F25: =E25*D25 -> 0
D26: SUBTOTAL ITEM 3.- | F26: =SUM(F25) -> 0 | H26: =F26+F23+F14 -> #REF!
A27: 4 - ESTRUCTURA STEEL FRAMING
A28: 4.1 | B28: PARED EXTERIOR Panel Steel Framing, compuesta por: Membrana Hydrofuga, Placa OSB 11,1, Perfil CSH PGC 100x40x0,9, Celulosa Pro, Placa OSB 11,1 | C28: m2 | E28: =7298/204 -> 35.77451 | F28: =E28*D28 -> 0 | I28: =F28 -> 0
A29: 4.2 | B29: PARED INTERIOR Panel Steel Framing, compuesta por: Placa OSB 11,1, Perfil CSH PGC 100x40x0,9, Celulosa Pro, Placa OSB 11,1 | C29: m2 | E29: =6060/204 -> 29.705882 | F29: =E29*D29 -> 0 | I29: =F29 -> 0
A30: 4.3 | B30: ENTREPISO Panel Steel Framing, compuesta por: Fenolico 18mm, Perfil CSH PGC 100x40x0,9, Lana de vidrio PV 100 c/aluminio | C30: m2 | E30: =7203/204 -> 35.308824 | F30: =E30*D30 -> 0
A31: 4.4 | B31: Armado de techo en madera con cabios, machimbre aislacion clavaderas y chapa , Panel MegaSytem C Foil/Prepintado-50 | C31: m2 | E31: =12030/308 -> 39.058442 | F31: =E31*D31 -> 0 | H31: =E31/106.34 -> 0.36729774
D32: SUBTOTAL ITEM 4.- | F32: =SUM(F28:F31) -> 0
A33: 5 - REVESTIMIENTOS
A34: 5.1 | B34: Revestimiento pared interior con placa de yeso de 12,5 encintado y masillado (no incluye lijado) | C34: m2 | E34: =3500/308 -> 11.363636 | F34: =E34*D34 -> 0
A35: 5.2 | B35: Revestimiento cielorraso interior PB y sanitarios PA, con placa de yeso de 12,5 encintado y masillado (no incluye lijado) | C35: m2 | E35: =E34 -> 11.363636 | F35: =E35*D35 -> 0
A36: 5.3 | B36: Revestimiento exterior EIFS con terminacion base coat o siding | C36: m2 | E36: =3920/308 -> 12.727273 | F36: =E36*D36 -> 0
A37: 5.3 | B37: Revestimiento tipo revear | C37: m2 | E37: =2900/308 -> 9.4155844 | F37: =E37*D37 -> 0
A38: 5.3 | B38: Colocacion de chapa en paredes exteriores | C38: m2 | E38: =2920/308 -> 9.4805195 | F38: =E38*D38 -> 0
D39: SUBTOTAL ITEM 5.- | F39: =SUM(F34:F38) -> 0 | I39: =F39 -> 0
A40: 5 - PISOS, CONTRAPISOS
...

Sheet gastos
A2: concepto | B2: fecha | C2: monto
A3: copias de planos | B3: 44942 | C3: 4073
A4: Nylon ferreteria y candado | B4: 44958 | C4: 10600
A5: cemento loma negra | B5: 44971 | C5: 13750
A6: combustible grupo elect. | B6: 44971 | C6: 1400
A7: termomagnetica y riel din centro electrico | B7: 44971 | C7: 4141.44
A8: 1 dia de alquiler grupo en alquilotodo | B8: 44974 | C8: 6000
A9: combustible grupo elect. | B9: 44979 | C9: 3000
A10: 2 kilos de clavo 1/2" | B10: 44985 | C10: 1900
A11: 2 kilos de clavo 1/2" | B11: 44999 | C11: 4750
C16: =SUM(C3:C15) -> 49614.44

Sheet Hoja3
E2: m3 | F2: 18.5
E3: m2 | F3: 119.3
E5: maquinaria 1 dia de trabajo, extraccion de material vegetal | F5: 50000
E6: mano de obra exc | F6: 0
E7: mano de obra compactado | F7: =(7000+5000)*5 -> 60000
A8: mano de obra x m2 | C8: =F8/F3 -> 3300 | E8: mano de obra H°A° | F8: =F3*3300 -> 393690 | I8: 6 | J8: 8 | K8: 10
A9: mano de obra x m3 | C9: =F8/F2 -> 21280.541 | E9: materiales H°A° | F9: =SUM(L14:L22) -> 494413.64 | I9: =209.47/12 -> 17.455833 | J9: =2110.66/12 -> 175.88833 | K9: =24.82/12 -> 2.0683333
E10: total costo-costo | F10: =SUM(F8:F9) -> 888103.64 | I10: 633 | J10: 1100.5 | K10: 1719
E12: 15% gastos generales | F12: =F10*0.15 -> 133215.55
F13: =F12+F10 -> 1021319.2
C14: =F14+F12 -> 439611.3 | E14: 15% de beneficio + 10% de imprevistos + 3% eventualidades + 1% de seguridad (29%) | F14: =F13*0.3 -> 306395.76 | H14: hierro | I14: =I10*I9 -> 11049.543 | J14: =J10*J9 -> 193565.11 | K14: =K10*K9 -> 3555.465 | L14: =SUM(I14:K14) -> 208170.12
F15: =F13+F14 -> 1327714.9 | G15: =F10*1.45 -> 1287750.3
E19: 3% ingresos brutos | F19: =F15*0.03 -> 39831.448 | H19: barras | J19: 14000 | K19: 18.5 | L19: =K19*J19 -> 259000
E20: 35% ganancias | F20: =F14*0.35 -> 107238.51 | H20: alambre | J20: 368 | K20: 10 | L20: =K20*J20 -> 3680
B21: costo m2 | C21: =F22/F2 -> 79718.103 | H21: clavos | J21: 544 | K21: 10 | L21: =K21*J21 -> 5440
E22: total sin IVA | F22: =F20+F19+F15 -> 1474784.9 | H22: madera | I22: 33.3 | J22: 0.35 | K22: 1555 | L22: =K22*J22*I22 -> 18123.525
B23: costo m3 | C23: =F22/F3 -> 12361.986
E24: TOTAL SIN MATERIALES Y SIN IVA | F24: =F28+F19+F20 -> 980371.27
F26: =F24-F20-F19 -> 833301.3 | H26: =F26/119.3 -> 6984.9229
A28: costo m2 sin materiales | C28: =F28/F3 -> 6984.9229 | E28: SUBTOTAL SIN MATERIALES | F28: =F15-F9 -> 833301.3
A29: costo m2 sin materiales | C29: =F28/F2 -> 45043.314 | G29: =F28-F8 -> 439611.3

Sheet Hoja7
A1: 1.2 | B1: Partida | C1: PAVIMENTOS | D1: M2
B2: Mano de obra | C2: OFICIAL ESPECIALIZADO | D2: hs | E2: 0 | F2: =80000/8+5789 -> 15789 | G2: =E2*F2 -> 0
B3: Mano de obra | C3: OFICIAL | D3: hs | E3: 2 | F3: =50000/8+5789 -> 12039 | G3: =E3*F3 -> 24078
B4: Mano de obra | C4: MEDIO OFICIAL | D4: hs | F4: =45000/8+5789 -> 11414 | G4: =E4*F4 -> 0
B5: Mano de obra | C5: AYUDANTE | D5: hs | E5: 1.2 | F5: =40000/8+5768 -> 10768 | G5: =E5*F5 -> 12921.6
B6: Mano de obra | C6: AYUDA DE GREMIO ayudante | D6: hs | F6: =F5 -> 10768 | G6: =E6*F6 -> 0
B7: SUBTOTAL MANO DE OBRA (A) | G7: =SUM(G2:G6) -> 36999.6
B8: Material | C8: Hierro barra | D8: ton | E8: 0.008 | F8: 1807030 | G8: =E8*F8 -> 14456.24
B9: Material | C9: Alambre negro | D9: kg | E9: 0.01 | F9: 7500 | G9: =E9*F9 -> 75
B10: Material | C10: tablas | D10: m2 | F10: =14500/2.88*3 -> 15104.167 | G10: =E10*F10 -> 0
B11: Material | C11: tirantes | D11: m2 | F11: =12500*3 -> 37500 | G11: =E11*F11 -> 0
B12: Material | C12: clavos | D12: kg | F12: 7500 | G12: =E12*F12 -> 0
B13: Material | C13: cemento | D13: kg | E13: 66 | F13: =13000/50 -> 260 | G13: =E13*F13 -> 17160
B14: Material | C14: arena | D14: m3 | E14: 0.15 | F14: 50000 | G14: =E14*F14 -> 7500
B15: Material | C15: piedra | D15: m3 | E15: 0.18 | F15: 50000 | G15: =E15*F15 -> 9000
B16: Material | G16: =E16*F16 -> 0
B17: Material | G17: =E17*F17 -> 0
B18: Material | G18: =E18*F18 -> 0
B19: Material
B20: Material
B21: Material
B22: SUBTOTAL MATERIAL (B) | G22: =SUM(G8:G21) -> 48191.24
B24: 1 | C24: MANO DE OBRA | D24: TOTAL (A) | G24: =G7 -> 36999.6
B25: 2 | C25: MATERIALES | D25: TOTAL (B) | G25: =G22 -> 48191.24
B26: 3 | C26: EQUIPOS | D26: TOTAL (C)
B27: 4 | C27: COSTO - COSTO | D27: (1 + 2 + 3) | G27: =SUM(G24:G26) -> 85190.84 | I27: =G27*1.95 -> 166122.14
B28: 5 | C28: GASTOS GENERALES | D28: D% x (4) | E28: 0.4 | G28: =+G27*E28 -> 34076.336
B29: 6 | C29: COSTO - COSTO + GASTOS GENERALES | D29: (4 + 5) | G29: =G28+G27 -> 119267.18
B30: 7 | C30: IMPREVISTOS Y EVENTUALIDADES | D30: E% x (6) | E30: 0.1 | G30: =+G29*E30 -> 11926.718
B31: 8 | C31: EPP-SEGURIDAD | D31: F% x (6) | E31: 0.1 | G31: =G29*E31 -> 11926.718
B32: 9 | C32: BENEFICIO | D32: G% x (6) | E32: 0.4 | G32: =G29*E32 -> 47706.87
B33: 10 | C33: COSTO TOTAL DEL TRABAJO | D33: (6 + 7 + 8 + 9) | G33: =G32+G31+G30+G29 -> 190827.48
B34: 11 | C34: COSTO TOTAL DEL TRABAJO SIN MATERIALES | D34: (10 - 1) | G34: =G33-G25 -> 142636.24
B35: 12 | C35: IMPUESTOS (IIBB - GANANCIAS) | D35: V % x (9) | E35: 0 | G35: =G33*E35 -> 0
B36: 13 | C36: GANANCIAS | E36: 0 | G36: =G32*E36 -> 0
B38: 16 | C38: PRECIO UNITARIO DE APLICACIÓN SIN MATERIALES | D38: (10 + 12 + 13) | G38: =G34+G35+G36 -> 142636.24 | I38: 1200 | J38: =G38/I38 -> 118.86353
A40: 1.2 | B40: Partida | C40: CAMARA | D40: m3
B41: Mano de obra | C41: OFICIAL ESPECIALIZADO | D41: hs | E41: 0 | F41: =F2 -> 15789 | G41: =E41*F41 -> 0
B42: Mano de obra | C42: OFICIAL | D42: hs | E42: 35 | F42: =F3 -> 12039 | G42: =E42*F42 -> 421365
B43: Mano de obra | C43: MEDIO OFICIAL | D43: hs | F43: =F4 -> 11414 | G43: =E43*F43 -> 0
...
